Workbook

Sheet 📌 COVER
A1: BNP PARIBAS SA — THREE-YEAR FINANCIAL ANALYSIS
A2: FY 2022 | FY 2023 | FY 2024
A3: IFRS financial analysis | ECB SSM regulated institution | All monetary figures in € millions unless stated
A6: ANALYST INFORMATION
A8: Analyst Name: | C8: Joy Lorna
A9: Role Target: | C9: Financial Analyst — Luxembourg Banking / Big 4
A10: Analysis Date: | C10: =DATE(2026,8,25) -> 46259
A11: Workbook Version: | C11: v2.2
A13: ENTITY OVERVIEW
A15: Legal Entity: | C15: BNP Paribas SA
A16: Headquarters: | C16: 16 Boulevard des Italiens, 75009 Paris, France
A17: Listed: | C17: Euronext Paris — Ticker: BNP (CAC 40)
A18: ISIN: | C18: FR0000131104
A20: Business Model: | C20: Universal bank — Retail, Corporate & Institutional
C21: Banking (CIB), Asset & Wealth Management
A22: Supervision: | C22: ECB SSM (Significant Institution under SSM)
C23: SREP annual cycle, G-SIB designation
A27: ANALYSIS SCOPE
A29: Period: | C29: FY 2022 | FY 2023 | FY 2024
A30: Reporting Standard: | C30: IFRS (as adopted by EU, including IFRS 9 and IFRS 17 where applicable)
A31: Currency: | C31: EUR (€ millions) unless stated
A32: Statements in Scope: | C32: Income Statement, Balance Sheet, Cash Flow, Analyst Note
A33: Ratio Families: | C33: 5 — Profitability, Liquidity, Capital, Asset Quality, Efficiency
A34: Regulatory Context: | C34: ECB SSM / SREP, CRR3 / CRD VI, IFRS 9 / IFRS 17, Pillar 3
A35: Data Preparation: | C35: Manual extraction from official BNP PDFs; standardised and source-verified in Excel. FY2022 analytical figures use BNP Paribas’ IFRS 17/9 restated comparative basis where applicable and are presented consistently with FY2023–FY2024. Reported-versus-restated differences are documented in IFRS17_RESTATEMENT_NOTE.
A37: DATASET SOURCES — OFFICIAL BNP PARIBAS PDF DOCUMENTS
A39: FY 2022
A40: 1 | C40: Consolidated Financial Statements — Year ended 31 December 2022 (annual, audited) — https://invest.bnpparibas/document/4q22-consolidated-financial-statements-annual-audited
A41: 2 | C41: Results as at 31 December 2022 — Press release — https://invest.bnpparibas/document/4q22-pr
A42: 3 | C42: 2022 Full-Year Results — Slides — https://invest.bnpparibas/document/4q22-slides
A43: 4 | C43: Universal Registration Document and Annual Financial Report 2022 — includes Pillar 3 risk reports — https://invest.bnpparibas/document/universal-registration-document-2022
A44: FY 2023
A45: 1 | C45: Consolidated Financial Statements — Year ended 31 December 2023 (annual, audited) — https://invest.bnpparibas/document/4q23-consolidated-financial-statements-annual-audited
A46: 2 | C46: Results as at 31 December 2023 — Press release — https://invest.bnpparibas/document/4q23-pr
A47: 3 | C47: 2023 Full-Year Results — Slides — https://invest.bnpparibas/document/4q23-slides
A48: 4 | C48: Universal Registration Document and Annual Financial Report 2023 — includes Pillar 3 risk reports — https://invest.bnpparibas/document/universal-registration-document-annual-financial-report-2023-pdf
A49: FY 2024
A50: 1 | C50: Consolidated Financial Statements — Year ended 31 December 2024 (unaudited figures) — https://invest.bnpparibas/document/4q24-cfsu
A51: 2 | C51: Fourth-Quarter and Full-Year 2024 Results — Press release — https://invest.bnpparibas/document/4q24-pr
A52: 3 | C52: Fourth-Quarter and 2024 Full-Year Results — Slides — https://invest.bnpparibas/document/4q24-slides
...

Sheet 🔎WORKBOOK SHEET MAP
A1: BNP PARIBAS — WORKBOOK SHEET MAP
A2: Navigation guide for the FY 2022–FY 2024 financial analysis workbook
A3: 24 worksheets | Financial statements, analyst note, ratios, analytical bridges, charts, sources, controls, and audit documentation
A5: WORKBOOK CONTENTS
A6: TAB # | B6: WORKSHEET | C6: PURPOSE
A7: 1 | B7: 📌 COVER | C7: Workbook identity, scope, sources, and disclaimer
A8: 2 | B8: 🔎WORKBOOK SHEET MAP | C8: Navigation index for every worksheet
A9: 3 | B9: 📊 EXECUTIVE_SUMMARY | C9: Executive KPI scorecard and key findings
A10: 4 | B10: 📝 ANALYST_NOTE | C10: PDF-ready performance narrative, risk flags, and forward outlook
A11: 5 | B11: 📄 INCOME_STATEMENT | C11: Three-year income statement and key metrics
A12: 6 | B12: 🏦 BALANCE_SHEET | C12: Three-year assets, liabilities, equity, and reconciliation
A13: 7 | B13: 💰 CASH_FLOW | C13: Three-year cash-flow statement and cash review
A14: 8 | B14: 🧮VARIANCE BRIDGE | C14: Year-on-year earnings attribution and reconciliation
A15: 9 | B15: 📈 RATIOS_PROFITABILITY | C15: Profitability and return ratios
A16: 10 | B16: 📈 RATIOS_LIQUIDITY | C16: Liquidity and funding ratios
A17: 11 | B17: 📈 RATIOS_CAPITAL | C17: Regulatory capital and RWA analysis
A18: 12 | B18: 📈 RATIOS_ASSET_QUALITY | C18: Credit quality and IFRS 9 analysis
... A30: 24 | B30: ANALYTICAL_INPUTS | C30: Visible sourced denominator inputs for profitability ratios
A32: Use this page as the workbook table of contents.

Sheet 📊 EXECUTIVE_SUMMARY
A1: BNP PARIBAS SA — EXECUTIVE KPI SCORECARD
A2: FY 2022–FY 2024 | IFRS | ECB SSM regulated institution
A3: All monetary values in €M unless stated | Live-linked to the workbook’s financial statements and ratio schedules
A5: STORY IN BRIEF
A6: Net income attributable to equity holders increased from €9,848M in restated FY2022 to €11,688M in FY2024, an 8.9% two-year CAGR. FY2024 combined 6.4% NBI growth with lower operating expenses; standard Cost of Risk increased slightly, while other net risk losses declined substantially. Capital and liquidity ratios remained above the regulatory or analytical comparison levels explicitly assessed in this workbook, while NPLs improved to 1.6%.
A10: METRIC | B10: FY 2022 Restated | C10: FY 2023 | D10: FY 2024 | E10: TREND | F10: SIGNAL
A11: EARNINGS & REVENUE
A12: Net Banking Income (€M) | B12: ='📄 INCOME_STATEMENT'!B15 -> 45430 | C12: ='📄 INCOME_STATEMENT'!C15 -> 45874 | D12: ='📄 INCOME_STATEMENT'!D15 -> 48831 | E12: ↗ | F12: Strong revenue growth
A13: Net Interest Income (€M) | B13: ='📄 INCOME_STATEMENT'!B10 -> 20933 | C13: ='📄 INCOME_STATEMENT'!C10 -> 19058 | D13: ='📄 INCOME_STATEMENT'!D10 -> 19524 | E13: ↘↗ | F13: Rate-cycle pressure
A14: Fee & Commission Income (€M) | B14: ='📄 INCOME_STATEMENT'!B11 -> 10165 | C14: ='📄 INCOME_STATEMENT'!C11 -> 9821 | D14: ='📄 INCOME_STATEMENT'!D11 -> 10701 | E14: ↘↗ | F14: Resilient recovery
A15: Operating Expenses (€M) | B15: ='📄 INCOME_STATEMENT'!B22 -> 29864 | C15: ='📄 INCOME_STATEMENT'!C22 -> 30956 | D15: ='📄 INCOME_STATEMENT'!D22 -> 30193 | E15: ↗↘ | F15: Costs eased in FY2024
A16: Cost of Risk (€M) | B16: ='📄 INCOME_STATEMENT'!B27 -> 3003 | C16: ='📄 INCOME_STATEMENT'!C27 -> 2907 | D16: ='📄 INCOME_STATEMENT'!D27 -> 2999 | E16: ↗↘ | F16: Standard Cost of Risk; +3.2% in FY2024
A17: Other net risk losses (€M) | B17: ='📄 INCOME_STATEMENT'!B28 -> 0 | C17: ='📄 INCOME_STATEMENT'!C28 -> 775 | D17: ='📄 INCOME_STATEMENT'!D28 -> 202 | E17: ↘ | F17: Declined substantially in FY2024
A18: Net Income — Equity Holders (€M) | B18: ='📄 INCOME_STATEMENT'!B44 -> 9848 | C18: ='📄 INCOME_STATEMENT'!C44 -> 10975 | D18: ='📄 INCOME_STATEMENT'!D44 -> 11688 | E18: ↗ | F18: Strong earnings growth
A20: PROFITABILITY & RETURNS
A21: Return on Equity (ROE) | B21: ='📈 RATIOS_PROFITABILITY'!C8 -> 0.082367652 | C21: ='📈 RATIOS_PROFITABILITY'!D8 -> 0.089599517 | D21: ='📈 RATIOS_PROFITABILITY'!E8 -> 0.092806467 | E21: ↗ | F21: Improving; below EU average
A22: Return on Tangible Equity (ROTE) | B22: ='📈 RATIOS_PROFITABILITY'!C9 -> 0.089017848 | C22: ='📈 RATIOS_PROFITABILITY'!D9 -> 0.097036304 | D22: ='📈 RATIOS_PROFITABILITY'!E9 -> 0.10065189 | E22: ↗ | F22: Improving; no external target assessed
A23: Return on Assets (ROA) | B23: ='📈 RATIOS_PROFITABILITY'!C10 -> 0.0037174946 | C23: ='📈 RATIOS_PROFITABILITY'!D10 -> 0.004176778 | D23: ='📈 RATIOS_PROFITABILITY'!E10 -> 0.0044135581 | E23: ↗ | F23: Within EU bank range
A24: Net Interest Margin (NIM) | B24: ='📈 RATIOS_PROFITABILITY'!C11 -> 0.020698128 | C24: ='📈 RATIOS_PROFITABILITY'!D11 -> 0.018198155 | D24: ='📈 RATIOS_PROFITABILITY'!E11 -> 0.01771155 | E24: ↘ | F24: At upper end of EU range
A25: Net Income Margin | B25: ='📈 RATIOS_PROFITABILITY'!C14 -> 0.21677306 | C25: ='📈 RATIOS_PROFITABILITY'!D14 -> 0.23924227 | D25: ='📈 RATIOS_PROFITABILITY'!E14 -> 0.23935615 | E25: ↗ | F25: Stable near 24%
A26: Earnings per Share (€) | B26: ='📈 RATIOS_PROFITABILITY'!C15 -> 7.52 | C26: ='📈 RATIOS_PROFITABILITY'!D15 -> 8.58 | D26: ='📈 RATIOS_PROFITABILITY'!E15 -> 9.57 | E26: ↗ | F26: Strong EPS growth
A28: CAPITAL & LIQUIDITY
A29: CET1 Ratio | B29: ='📈 RATIOS_CAPITAL'!C8 -> 0.1233 | C29: ='📈 RATIOS_CAPITAL'!D8 -> 0.132 | D29: ='📈 RATIOS_CAPITAL'!E8 -> 0.1287 | E29: ↗↘ | F29: Regulatory comparison only; no SREP threshold asserted
A30: Tier 1 Ratio | B30: ='📈 RATIOS_CAPITAL'!C9 -> 0.1389 | C30: ='📈 RATIOS_CAPITAL'!D9 -> 0.1528 | D30: ='📈 RATIOS_CAPITAL'!E9 -> 0.1493 | E30: ↗↘ | F30: Above stated base reference
A31: Total Capital Ratio | B31: ='📈 RATIOS_CAPITAL'!C10 -> 0.1619 | C31: ='📈 RATIOS_CAPITAL'!D10 -> 0.173 | D31: ='📈 RATIOS_CAPITAL'!E10 -> 0.1713 | E31: ↗↘ | F31: Above stated base reference
A32: Leverage Ratio | B32: ='📈 RATIOS_CAPITAL'!C11 -> 0.0436 | C32: ='📈 RATIOS_CAPITAL'!D11 -> 0.0458 | D32: ='📈 RATIOS_CAPITAL'!E11 -> 0.0462 | E32: ↗ | F32: Above 3% base reference
A33: Risk-Weighted Assets (€M) | B33: ='📈 RATIOS_CAPITAL'!B21 -> 744851 | C33: ='📈 RATIOS_CAPITAL'!C21 -> 703694 | D33: ='📈 RATIOS_CAPITAL'!D21 -> 762247 | E33: ↘↗ | F33: Managed capital intensity
A34: Liquidity Coverage Ratio (LCR) | B34: ='📈 RATIOS_LIQUIDITY'!C8 -> 1.29 | C34: ='📈 RATIOS_LIQUIDITY'!D8 -> 1.48 | D34: ='📈 RATIOS_LIQUIDITY'!E8 -> 1.37 | E34: ↗↘ | F34: Above 100% minimum
A35: Net Stable Funding Ratio (NSFR) | B35: ='📈 RATIOS_LIQUIDITY'!C9 -> 1.1505 | C35: ='📈 RATIOS_LIQUIDITY'!D9 -> 1.1592 | D35: ='📈 RATIOS_LIQUIDITY'!E9 -> 1.1175 | E35: → | F35: Above 100% minimum
A36: Loan-to-Deposit Ratio | B36: ='📈 RATIOS_LIQUIDITY'!C11 -> 0.85017102 | C36: ='📈 RATIOS_LIQUIDITY'!D11 -> 0.86915267 | D36: ='📈 RATIOS_LIQUIDITY'!E11 -> 0.86982163 | E36: → | F36: Deposits exceed customer loans
A38: ASSET QUALITY & EFFICIENCY
A39: NPL Ratio | B39: ='📈 RATIOS_ASSET_QUALITY'!C8 -> 0.017 | C39: ='📈 RATIOS_ASSET_QUALITY'!D8 -> 0.017 | D39: ='📈 RATIOS_ASSET_QUALITY'!E8 -> 0.016 | E39: ↘ | F39: Better than EU average
A40: Coverage Ratio | B40: ='📈 RATIOS_ASSET_QUALITY'!C9 -> 0.725 | C40: ='📈 RATIOS_ASSET_QUALITY'!D9 -> 0.717 | D40: ='📈 RATIOS_ASSET_QUALITY'!E9 -> 0.697 | E40: ↘ | F40: Adequate; declining buffer
A41: Cost of Risk (bps) | B41: ='📈 RATIOS_ASSET_QUALITY'!C11 -> 31 | C41: ='📈 RATIOS_ASSET_QUALITY'!D11 -> 32 | D41: ='📈 RATIOS_ASSET_QUALITY'!E11 -> 33 | E41: ↗ | F41: Below ECB Q2 2024 sector reference
A42: Stage 1 ECL (€M) | B42: ='📈 RATIOS_ASSET_QUALITY'!C12 -> 2035 | C42: ='📈 RATIOS_ASSET_QUALITY'!D12 -> 1938 | D42: ='📈 RATIOS_ASSET_QUALITY'!E12 -> 1785 | E42: ↘ | F42: Lower performing ECL
A43: Stage 2 ECL (€M) | B43: ='📈 RATIOS_ASSET_QUALITY'!C13 -> 2860 | C43: ='📈 RATIOS_ASSET_QUALITY'!D13 -> 2416 | D43: ='📈 RATIOS_ASSET_QUALITY'!E13 -> 1939 | E43: ↘ | F43: Lower lifetime ECL
A44: Stage 3 Allowance (€M) | B44: ='📈 RATIOS_ASSET_QUALITY'!C14 -> 13616 | C44: ='📈 RATIOS_ASSET_QUALITY'!D14 -> 13361 | D44: ='📈 RATIOS_ASSET_QUALITY'!E14 -> 13457 | E44: → | F44: Stable doubtful allowance
A45: Cost-to-Income Ratio (CIR) | B45: ='📈 RATIOS_EFFICIENCY'!C8 -> 0.65736298 | C45: ='📈 RATIOS_EFFICIENCY'!D8 -> 0.6748049 | D45: ='📈 RATIOS_EFFICIENCY'!E8 -> 0.61831623 | E45: ↗↘ | F45: Below 66% analytical comparison
A46: Operating Leverage (pp) | B46: ="n/a" -> n/a | C46: ='📈 RATIOS_EFFICIENCY'!D12 -> -2.6792487 | D46: ='📈 RATIOS_EFFICIENCY'!E12 -> 8.9107058 | E46: ↗ | F46: Positive in FY2024
A49: KEY FINDINGS
...

Sheet 📝 ANALYST_NOTE
A1: BNP PARIBAS SA — FINANCIAL ANALYSIS NOTE
A2: FY 2022–FY 2024 | Analyst-style performance, risk, and outlook assessment
A3: Prepared by Joy Lorna | Portfolio demonstration | All monetary values in €M unless stated
A5: EXECUTIVE ASSESSMENT
A6: BNP Paribas delivered improving earnings and returns over FY2022–FY2024. Net income attributable to equity holders rose from €9,848M on the restated FY2022 basis to €11,688M in FY2024, an 8.9% two-year CAGR, while CIR improved to 61.83%. CET1 was 12.87%, LCR 137%, and NSFR 111.75% in FY2024; these are assessed only against the regulatory or analytical comparison levels explicitly documented in the workbook.
A10: KEY FINANCIAL SNAPSHOT
A11: METRIC | B11: FY 2022 Restated | C11: FY 2023 | D11: FY 2024 | E11: 3Y / FY2024 VIEW | F11: ANALYST INTERPRETATION
A12: Net Banking Income (€M) | B12: ='📄 INCOME_STATEMENT'!B15 -> 45430 | C12: ='📄 INCOME_STATEMENT'!C15 -> 45874 | D12: ='📄 INCOME_STATEMENT'!D15 -> 48831 | E12: 6.4% FY2024 growth | F12: Revenue momentum strengthened
A13: Net Income — Equity Holders (€M) | B13: ='📄 INCOME_STATEMENT'!B44 -> 9848 | C13: ='📄 INCOME_STATEMENT'!C44 -> 10975 | D13: ='📄 INCOME_STATEMENT'!D44 -> 11688 | E13: =TEXT('📈 RATIOS_PROFITABILITY'!E16,"0.0%")&" Net Income 2-Year CAGR (FY22–FY24)" -> 8.9% Net Income 2-Year CAGR (FY22–FY24) | F13: Earnings growth outpaced revenue
A14: ROE | B14: ='📈 RATIOS_PROFITABILITY'!C8 -> 0.082367652 | C14: ='📈 RATIOS_PROFITABILITY'!D8 -> 0.089599517 | D14: ='📈 RATIOS_PROFITABILITY'!E8 -> 0.092806467 | E14: 9.28% FY2024 | F14: Improving but below stronger EU peers
A15: ROTE | B15: ='📈 RATIOS_PROFITABILITY'!C9 -> 0.089017848 | C15: ='📈 RATIOS_PROFITABILITY'!D9 -> 0.097036304 | D15: ='📈 RATIOS_PROFITABILITY'!E9 -> 0.10065189 | E15: 10.07% FY2024 | F15: Positive trajectory; no external target assessed
A16: Cost-to-Income Ratio | B16: ='📈 RATIOS_EFFICIENCY'!C8 -> 0.65736298 | C16: ='📈 RATIOS_EFFICIENCY'!D8 -> 0.6748049 | D16: ='📈 RATIOS_EFFICIENCY'!E8 -> 0.61831623 | E16: 61.83% FY2024 | F16: Below the 66% analytical comparison
A17: CET1 Ratio | B17: ='📈 RATIOS_CAPITAL'!C8 -> 0.1233 | C17: ='📈 RATIOS_CAPITAL'!D8 -> 0.132 | D17: ='📈 RATIOS_CAPITAL'!E8 -> 0.1287 | E17: Regulatory comparison only | F17: Strong reported capital ratio; no SREP threshold asserted
A18: Liquidity Coverage Ratio (LCR) | B18: ='📈 RATIOS_LIQUIDITY'!C8 -> 1.29 | C18: ='📈 RATIOS_LIQUIDITY'!D8 -> 1.48 | D18: ='📈 RATIOS_LIQUIDITY'!E8 -> 1.37 | E18: 137% FY2024 | F18: Above the 100% regulatory minimum
A19: NPL Ratio | B19: ='📈 RATIOS_ASSET_QUALITY'!C8 -> 0.017 | C19: ='📈 RATIOS_ASSET_QUALITY'!D8 -> 0.017 | D19: ='📈 RATIOS_ASSET_QUALITY'!E8 -> 0.016 | E19: 1.6% FY2024 | F19: Better than the ~2.3% EU reference
A20: Coverage Ratio | B20: ='📈 RATIOS_ASSET_QUALITY'!C9 -> 0.725 | C20: ='📈 RATIOS_ASSET_QUALITY'!D9 -> 0.717 | D20: ='📈 RATIOS_ASSET_QUALITY'!E9 -> 0.697 | E20: 69.7% FY2024 | F20: Adequate but declining
A21: Net Stable Funding Ratio (NSFR) | B21: ='📈 RATIOS_LIQUIDITY'!C9 -> 1.1505 | C21: ='📈 RATIOS_LIQUIDITY'!D9 -> 1.1592 | D21: ='📈 RATIOS_LIQUIDITY'!E9 -> 1.1175 | E21: 111.75% FY2024 | F21: Above the 100% regulatory minimum
A23: 1. EARNINGS PERFORMANCE
A24: Revenue was broadly stable in FY2023 before accelerating in FY2024. NBI increased from €45,430M in restated FY2022 to €48,831M in FY2024. NII declined 9.0% in FY2023 and recovered 2.4% in FY2024, while fees and trading strengthened. Operating expenses fell 2.5% in FY2024. Standard Cost of Risk increased from €2,907M to €2,999M, but other net risk losses declined from €775M to €202M; together these movements supported the 37.4% rise in operating income.
A31: 2. BALANCE SHEET, FUNDING, AND LIQUIDITY
A32: Total assets reached €2,704,908M in FY2024, 4.4% above FY2023. Customer loans were €900,141M and customer deposits €1,034,857M, leaving the loan-to-deposit ratio at 86.98%. This supports a deposit-funded customer lending profile, although the ratio does not capture the Group’s full funding structure. LCR and NSFR remained above the 100% minimum at 137% and 111.75%; HQLA declined to €380,615M.
A38: 3. CASH FLOW ASSESSMENT
A39: The cash-flow statement shows significant operating outflows, including €97,376M in FY2024, largely driven by movements in financial assets and liabilities. The IAS 7 cash-equivalent roll-forward now reconciles exactly in all three years: €317,698M in FY2022, €282,579M in FY2023, and €178,212M in FY2024. These measures include central-bank cash, on-demand balances with credit institutions, and published adjustments, so they are not equivalent to the single balance-sheet line ‘Cash and balances at central banks’.
A46: 4. PROFITABILITY AND EFFICIENCY
A47: ROE improved from 8.24% on the restated FY2022 basis to 9.28%, ROTE from 8.90% to 10.07%, and EPS from €7.52 to €9.57. Net income margin increased from 21.68% to 23.94%. CIR improved to 61.83% in FY2024, below the workbook’s 66% analytical comparison, while NIM declined from 2.07% to 1.77%.
A52: 5. CAPITAL AND CREDIT RISK
A53: Capital remains a core strength. FY2024 CET1 was 12.87%; regulatory reference levels are used for analytical comparison only, and no BNP-specific SREP threshold is asserted. Tier 1, total capital, and leverage ratios also remain above their stated comparison levels. RWA rose to €762,247M in FY2024, explaining why capital ratios moderated from FY2023 despite higher capital balances. Credit quality improved as NPL declined to 1.6%, while coverage fell from 72.5% to 69.7%, leaving less protection if macroeconomic conditions weaken.
A58: 6. KEY RISKS AND FORWARD OUTLOOK
A59: Base case: earnings remain resilient but may grow more slowly if lower policy rates pressure NII. Fee and trading income, cost discipline, and controlled credit costs could partly offset that effect. The key forward-looking sensitivities are continued NIM pressure, Stage 2/3 migration, coverage, RWA growth, and liquidity-buffer trends; these are analytical scenarios rather than sourced BNP forecasts.
... A72: Data were manually extracted from official BNP Paribas annual-results, annual-report, and Pillar 3 documents, standardised in Excel, and cross-checked through the live control register. FY2022 figures affected by IFRS 17/9 use BNP’s restated disclosures for comparability with FY2023–FY2024; reported and restated values are retained separately in IFRS17_RESTATEMENT_NOTE. The analysis excludes forecasts, valuation, consensus estimates, and stress testing.

Sheet 📄 INCOME_STATEMENT
A1: BNP PARIBAS SA — CONSOLIDATED INCOME STATEMENT
A2: FY 2022–FY 2024 | IFRS banking presentation | Net Banking Income format
A3: All figures in €M except percentages, basis points, and per-share data
A4: FY2024 earnings strengthened as NBI grew 6.4% and operating expenses declined 2.5%. Standard Cost of Risk increased 3.2%, while other net risk losses fell 73.9%, lifting operating income 37.4% and net income attributable to equity holders to €11,688M.
A7: LINE ITEM | B7: FY 2022 Restated | C7: FY 2023 | D7: FY 2024 | E7: Δ% 22→23 | F7: Δ% 23→24
A9: NET BANKING INCOME
A10: Net Interest Income | B10: 20933 | C10: 19058 | D10: 19524 | E10: =(C10/B10)-1 -> -0.08957149 | F10: =(D10/C10)-1 -> 0.024451674
A11: Net Fee & Commission Income | B11: 10165 | C11: 9821 | D11: 10701 | E11: =(C11/B11)-1 -> -0.033841613 | F11: =(D11/C11)-1 -> 0.08960391
A12: Net Trading Income | B12: 9352 | C12: 10346 | D12: 11569 | E12: =(C12/B12)-1 -> 0.10628743 | F12: =(D12/C12)-1 -> 0.11820994
A13: Net Income from Other Activities | B13: 2982 | C13: 4235 | D13: 4377 | E13: =(C13/B13)-1 -> 0.42018779 | F13: =(D13/C13)-1 -> 0.033530106
A15: TOTAL NET BANKING INCOME | B15: 45430 | C15: 45874 | D15: 48831 | E15: =(C15/B15)-1 -> 0.0097732776 | F15: =(D15/C15)-1 -> 0.064459171
A17: Identified NBI components subtotal | B17: =SUM(B10:B13) -> 43432 | C17: =SUM(C10:C13) -> 43460 | D17: =SUM(D10:D13) -> 46171
A18: OPERATING EXPENSES
A19: Operating expenses | B19: 27560 | C19: 28713 | D19: 27803 | E19: =(C19/B19)-1 -> 0.041835994 | F19: =(D19/C19)-1 -> -0.031692961
A20: Depreciation & Amortisation | B20: 2304 | C20: 2243 | D20: 2390 | E20: =(C20/B20)-1 -> -0.026475694 | F20: =(D20/C20)-1 -> 0.065537227
A22: TOTAL OPERATING EXPENSES | B22: =B19+B20 -> 29864 | C22: =C19+C20 -> 30956 | D22: =D19+D20 -> 30193 | E22: =(C22/ABS(B22))-1 -> 0.036565765 | F22: =(D22/ABS(C22))-1 -> -0.024647887
A25: GROSS OPERATING INCOME | B25: =B15-B22 -> 15566 | C25: =C15-C22 -> 14918 | D25: =D15-D22 -> 18638 | E25: =(C25/B25)-1 -> -0.041629192 | F25: =(D25/C25)-1 -> 0.24936319
A27: Cost of Risk | B27: 3003 | C27: 2907 | D27: 2999 | E27: =(C27/ABS(B27))-1 -> -0.031968032 | F27: =(D27/ABS(C27))-1 -> 0.031647747
A28: Other net losses for risk on financial instruments | B28: 0 | C28: 775 | D28: 202 | E28: =IFERROR(C28/B28-1,"n/a") -> n/a | F28: =(D28/C28)-1 -> -0.73935484
A29: TOTAL RISK-RELATED CHARGES | B29: =B27+B28 -> 3003 | C29: =C27+C28 -> 3682 | D29: =D27+D28 -> 3201 | E29: =(C29/ABS(B29))-1 -> 0.22610723 | F29: =(D29/ABS(C29))-1 -> -0.13063552
A31: OPERATING INCOME | B31: =B25-B29 -> 12563 | C31: =C25-C29 -> 11236 | D31: =D25-D29 -> 15437 | E31: =(C31/B31)-1 -> -0.10562764 | F31: =(D31/C31)-1 -> 0.3738875
A33: Share of earnings of equity-method entities | B33: 655 | C33: 593 | D33: 701
A34: Net gain on non-current assets | B34: -253 | C34: -104 | D34: -191
A35: Goodwill impact | B35: 249 | C35: 0 | D35: 241
A37: PRE-TAX INCOME | B37: =B31+B33+B34+B35 -> 13214 | C37: =C31+C33+C34+C35 -> 11725 | D37: =D31+D33+D34+D35 -> 16188 | E37: =(C37/B37)-1 -> -0.11268352 | F37: =(D37/C37)-1 -> 0.38063966
A39: CORPORATE INCOME TAX | B39: 3653 | C39: 3266 | D39: 4001
A40: NET INCOME FROM CONTINUING ACTIVITIES | B40: =B37-B39 -> 9561 | C40: =C37-C39 -> 8459 | D40: =D37-D39 -> 12187
A41: Net income from discontinued activities | B41: 687 | C41: 2947 | D41: 0
A42: NET INCOME | B42: =B40+B41 -> 10248 | C42: =C40+C41 -> 11406 | D42: =D40+D41 -> 12187
A43: Net income attributable to minority interests | B43: 400 | C43: 431 | D43: 499
A44: NET INCOME ATTRIBUTABLE TO EQUITY HOLDERS | B44: =B42-B43 -> 9848 | C44: =C42-C43 -> 10975 | D44: =D42-D43 -> 11688 | E44: =(C44/B44)-1 -> 0.11443948 | F44: =(D44/C44)-1 -> 0.064965831
A47: KEY METRICS
A48: Cost-to-Income Ratio (CIR) | B48: =B22/B15 -> 0.65736298 | C48: =C22/C15 -> 0.6748049 | D48: =D22/D15 -> 0.61831623
A49: Cost of Risk (bps) | B49: 31 | C49: 32 | D49: 33
A50: Net Income Margin | B50: =B44/B15 -> 0.21677306 | C50: =C44/C15 -> 0.23924227 | D50: =D44/D15 -> 0.23935615
A51: EPS — Group Share (€) | B51: 7.52 | C51: 8.58 | D51: 9.57

Sheet 🏦 BALANCE_SHEET
A1: BNP PARIBAS SA — CONSOLIDATED BALANCE SHEET
A2: FY 2022–FY 2024 | IFRS banking presentation
A3: All figures in €M | Period end: 31 December
A4: Total assets increased to €2,704,908M in FY2024, supported by customer-loan growth and higher securities balances. Customer deposits grew 4.7%, while total equity reached €134,141M and the balance sheet remained fully reconciled.
A7: ASSETS | B7: 44926 | C7: 45291 | D7: 45657 | E7: Δ% 22→23 | F7: Δ% 23→24
A9: Cash and balances at central banks | B9: 318560 | C9: 288259 | D9: 182496 | E9: =(C9/B9)-1 -> -0.095118659 | F9: =(D9/C9)-1 -> -0.36690268
A10: Financial instruments at fair value through profit or loss
A11: Securities | B11: 166077 | C11: 211634 | D11: 267357 | E11: =(C11/B11)-1 -> 0.27431252 | F11: =(D11/C11)-1 -> 0.2632989
A12: Loans and repurchase agreements | B12: 191125 | C12: 227175 | D12: 225699 | E12: =(C12/B12)-1 -> 0.18862001 | F12: =(D12/C12)-1 -> -0.0064971938
A13: Derivative financial instruments | B13: 327932 | C13: 292079 | D13: 322631 | E13: =(C13/B13)-1 -> -0.10933059 | F13: =(D13/C13)-1 -> 0.10460184
A14: Derivatives used for hedging purposes | B14: 25401 | C14: 21692 | D14: 20851 | E14: =(C14/B14)-1 -> -0.14601787 | F14: =(D14/C14)-1 -> -0.038770053
A15: Financial assets at fair value through equity
A16: Debt securities | B16: 35878 | C16: 50274 | D16: 71430 | E16: =(C16/B16)-1 -> 0.40124868 | F16: =(D16/C16)-1 -> 0.42081394
A17: Equity securities | B17: 2188 | C17: 2275 | D17: 1610 | E17: =(C17/B17)-1 -> 0.03976234 | F17: =(D17/C17)-1 -> -0.29230769
A18: Financial assets at amortised cost
A19: Loans and advances to credit institutions | B19: 32616 | C19: 24335 | D19: 31147 | E19: =(C19/B19)-1 -> -0.25389379 | F19: =(D19/C19)-1 -> 0.27992603
A20: Loans and advances to customers | B20: 857020 | C20: 859200 | D20: 900141 | E20: =(C20/B20)-1 -> 0.0025436979 | F20: =(D20/C20)-1 -> 0.04765014
A21: Debt securities | B21: 114014 | C21: 121161 | D21: 146975 | E21: =(C21/B21)-1 -> 0.062685284 | F21: =(D21/C21)-1 -> 0.21305536
A22: Remeasurement adjustment on interest-rate risk hedged portfolios | B22: -7477 | C22: -2661 | D22: -758 | E22: =(C22/B22)-1 -> -0.6441086 | F22: =(D22/C22)-1 -> -0.71514468
A23: Investments and other assets related to insurance activities | B23: 245475 | C23: 257098 | D23: 286849 | E23: =(C23/B23)-1 -> 0.047349017 | F23: =(D23/C23)-1 -> 0.11571852
A24: Current and deferred tax assets | B24: 5932 | C24: 6556 | D24: 6215 | E24: =(C24/B24)-1 -> 0.10519218 | F24: =(D24/C24)-1 -> -0.052013423
A25: Accrued income and other assets | B25: 208543 | C25: 170758 | D25: 174147 | E25: =(C25/B25)-1 -> -0.18118565 | F25: =(D25/C25)-1 -> 0.019846801
A26: Equity-method investments | B26: 6073 | C26: 6751 | D26: 7862 | E26: =(C26/B26)-1 -> 0.11164169 | F26: =(D26/C26)-1 -> 0.16456821
A27: Property, plant and equipment and investment property | B27: 38468 | C27: 45222 | D27: 50314 | E27: =(C27/B27)-1 -> 0.1755745 | F27: =(D27/C27)-1 -> 0.11260006
A28: Intangible assets | B28: 3790 | C28: 4142 | D28: 4392 | E28: =(C28/B28)-1 -> 0.092875989 | F28: =(D28/C28)-1 -> 0.060357315
A29: Goodwill | B29: 5294 | C29: 5549 | D29: 5550 | E29: =(C29/B29)-1 -> 0.048167737 | F29: =(D29/C29)-1 -> 0.00018021265
A31: TOTAL ASSETS | B31: 2663748 | C31: 2591499 | D31: 2704908 | E31: =(C31/B31)-1 -> -0.027123061 | F31: =(D31/C31)-1 -> 0.043761931
A34: LIABILITIES | B34: 44926 | C34: 45291 | D34: 45657 | E34: Δ% 22→23 | F34: Δ% 23→24
A36: Deposits from central banks | B36: 3054 | C36: 3374 | D36: 3366 | E36: =(C36/B36)-1 -> 0.10478062 | F36: =(D36/C36)-1 -> -0.0023710729
A37: Financial instruments at fair value through profit or loss
A38: Securities | B38: 99155 | C38: 104910 | D38: 79958 | E38: =(C38/B38)-1 -> 0.058040442 | F38: =(D38/C38)-1 -> -0.23784196
A39: Deposits and repurchase agreements | B39: 234076 | C39: 273614 | D39: 304817 | E39: =(C39/B39)-1 -> 0.16891095 | F39: =(D39/C39)-1 -> 0.11404022
A40: Issued debt securities and subordinated debt | B40: 65578 | C40: 83763 | D40: 104934 | E40: =(C40/B40)-1 -> 0.27730336 | F40: =(D40/C40)-1 -> 0.25274883
A41: Derivative financial instruments | B41: 300121 | C41: 278892 | D41: 301953 | E41: =(C41/B41)-1 -> -0.070734804 | F41: =(D41/C41)-1 -> 0.082687922
A42: Derivatives used for hedging purposes | B42: 40001 | C42: 38011 | D42: 36864 | E42: =(C42/B42)-1 -> -0.049748756 | F42: =(D42/C42)-1 -> -0.030175476
A43: Financial liabilities at amortised cost
A44: Deposits from credit institutions | B44: 124718 | C44: 95175 | D44: 66872 | E44: =(C44/B44)-1 -> -0.2368784 | F44: =(D44/C44)-1 -> -0.29737851
A45: Deposits from customers | B45: 1008056 | C45: 988549 | D45: 1034857 | E45: =(C45/B45)-1 -> -0.019351107 | F45: =(D45/C45)-1 -> 0.046844415
A46: Debt securities | B46: 155359 | C46: 191482 | D46: 198119 | E46: =(C46/B46)-1 -> 0.23251308 | F46: =(D46/C46)-1 -> 0.034661221
A47: Subordinated debt | B47: 24160 | C47: 24743 | D47: 31799 | E47: =(C47/B47)-1 -> 0.024130795 | F47: =(D47/C47)-1 -> 0.28517156
...

Sheet 💰 CASH_FLOW
A1: BNP PARIBAS SA — CONSOLIDATED CASH FLOW STATEMENT
A2: FY 2022–FY 2024 | IFRS (IAS 7) | Indirect method
A3: All figures in €M except percentages
A4: FY2024 cash generation was affected by a €97,376M operating outflow, mainly from movements in financial assets and liabilities. Investing cash flow was near neutral, while financing activities produced a €6,418M outflow.
A7: CASH-FLOW ITEM | B7: FY 2022 | C7: FY 2023 | D7: FY 2024 | E7: Δ% 22→23 | F7: Δ% 23→24
A9: A. OPERATING ACTIVITIES
A10: Pre-tax income from continuing activities | B10: 13214 | C10: 11725 | D10: 16188 | E10: =(C10/B10)-1 -> -0.11268352 | F10: =(D10/C10)-1 -> 0.38063966
A11: Pre-tax income from discontinued activities | B11: 823 | C11: 3658 | D11: 0 | E11: =(C11/B11)-1 -> 3.4447145 | F11: =(D11/C11)-1 -> -1
A12: Non-monetary items included in pre-tax net income and other adjustments | B12: 21838 | C12: 8495 | D12: 11094 | E12: =(C12/B12)-1 -> -0.61099918 | F12: =(D12/C12)-1 -> 0.30594467
A13: Net depreciation/amortisation expense | B13: 6465 | C13: 6245 | D13: 7272 | E13: =(C13/B13)-1 -> -0.034029389 | F13: =(D13/C13)-1 -> 0.16445156
A14: Impairment of goodwill and other non-current assets | B14: 91 | C14: -32 | D14: 21 | E14: =(C14/B14)-1 -> -1.3516484 | F14: =(D14/C14)-1 -> -1.65625
A15: Net addition to provisions | B15: 3193 | C15: 3646 | D15: 3023 | E15: =(C15/B15)-1 -> 0.14187285 | F15: =(D15/C15)-1 -> -0.17087219
A16: Variation of assets/liabilities related to insurance contracts | B16: -837 | C16: -6240 | D16: 3181 | E16: =(C16/B16)-1 -> 6.4551971 | F16: =(D16/C16)-1 -> -1.5097756
A17: Share of earnings of equity-method entities | B17: -655 | C17: -593 | D17: -701 | E17: =(C17/B17)-1 -> -0.094656489 | F17: =(D17/C17)-1 -> 0.18212479
A18: Net income from investing activities | B18: 265 | C18: -3600 | D18: -277 | E18: =(C18/B18)-1 -> -14.584906 | F18: =(D18/C18)-1 -> -0.92305556
A19: Net income (expense) from financing activities | B19: -1192 | C19: 506 | D19: -604 | E19: =(C19/B19)-1 -> -1.4244966 | F19: =(D19/C19)-1 -> -2.1936759
A20: Other movements | B20: 14508 | C20: 8563 | D20: -821 | E20: =(C20/B20)-1 -> -0.40977392 | F20: =(D20/C20)-1 -> -1.0958776
A21: Net decrease related to assets and liabilities | B21: -88712 | C21: -58119 | D21: -124658 | E21: =(C21/B21)-1 -> -0.34485752 | F21: =(D21/C21)-1 -> 1.1448752
... A27: NET CASH FROM OPERATING ACTIVITIES | B27: -52837 | C27: -34241 | D27: -97376 | E27: =(C27/B27)-1 -> -0.35195034 | F27: =(D27/C27)-1 -> 1.8438422
A29: B. INVESTING ACTIVITIES
A30: Net increase related to acquisitions and disposals of consolidated entities | B30: 366 | C30: 9520 | D30: 1956 | E30: =(C30/B30)-1 -> 25.010929 | F30: =(D30/C30)-1 -> -0.79453782
A31: Net decrease related to property, plant and equipment and intangible assets | B31: -2529 | C31: -2216 | D31: -2136 | E31: =(C31/B31)-1 -> -0.12376433 | F31: =(D31/C31)-1 -> -0.036101083
A33: NET CASH FROM INVESTING ACTIVITIES | B33: =B30+B31 -> -2163 | C33: =C30+C31 -> 7304 | D33: =D30+D31 -> -180 | E33: =(C33/B33)-1 -> -4.3767915 | F33: =(D33/C33)-1 -> -1.024644
A35: C. FINANCING ACTIVITIES
A36: Decrease in cash and cash equivalents related to transactions with shareholders | B36: -2578 | C36: -8698 | D36: -8756 | E36: =(C36/B36)-1 -> 2.3739333 | F36: =(D36/C36)-1 -> 0.0066681996
A37: Increase in cash and cash equivalents generated by other financing activities | B37: 11828 | C37: 4022 | D37: 2338 | E37: =(C37/B37)-1 -> -0.65995942 | F37: =(D37/C37)-1 -> -0.41869717
A39: NET CASH FROM FINANCING ACTIVITIES | B39: =B36+B37 -> 9250 | C39: =C36+C37 -> -4676 | D39: =D36+D37 -> -6418 | E39: =(C39/B39)-1 -> -1.5055135 | F39: =(D39/C39)-1 -> 0.37254063
A40: EFFECT OF MOVEMENT IN EXCHANGE RATES | B40: 1030 | C40: -3506 | D40: -393 | E40: =(C40/B40)-1 -> -4.4038835 | F40: =(D40/C40)-1 -> -0.88790645
A41: NET DECREASE IN CASH AND CASH EQUIVALENTS | B41: -44720 | C41: -35119 | D41: -104367 | E41: =(C41/B41)-1 -> -0.21469141 | F41: =(D41/C41)-1 -> 1.9718101
A44: CASH AND CASH EQUIVALENTS RECONCILIATION | B44: FY 2022 | C44: FY 2023 | D44: FY 2024 | E44: Δ% 22→23 | F44: Δ% 23→24
A45: Opening cash and cash equivalents | B45: 362418 | C45: 317698 | D45: 282579 | E45: =IFERROR(C45/B45-1,"") -> -0.12339343 | F45: =IFERROR(D45/C45-1,"") -> -0.11054209
A46: Net decrease in cash and cash equivalents | B46: =B41 -> -44720 | C46: =C41 -> -35119 | D46: =D41 -> -104367 | E46: =IFERROR(C46/B46-1,"") -> -0.21469141 | F46: =IFERROR(D46/C46-1,"") -> 1.9718101
A47: Calculated closing cash and cash equivalents | B47: =B45+B46 -> 317698 | C47: =C45+C46 -> 282579 | D47: =D45+D46 -> 178212 | E47: =IFERROR(C47/B47-1,"") -> -0.11054209 | F47: =IFERROR(D47/C47-1,"") -> -0.36933742
A48: Reported closing cash and cash equivalents | B48: 317698 | C48: 282579 | D48: 178212 | E48: =IFERROR(C48/B48-1,"") -> -0.11054209 | F48: =IFERROR(D48/C48-1,"") -> -0.36933742
A49: ROLL-FORWARD RECONCILIATION CHECK | B49: =B47-B48 -> 0 | C49: =C47-C48 -> 0 | D49: =D47-D48 -> 0 | E49: €0M expected | F49: PASS when all years = €0M
A51: CLOSING CASH-EQUIVALENT COMPOSITION | B51: FY 2022 | C51: FY 2023 | D51: FY 2024 | E51: STATUS | F51: SOURCE BASIS
A52: Cash and amounts due from central banks | B52: 318581 | C52: 288279 | D52: 182511 | E52: Published component | F52: BNP consolidated cash-flow statement
A53: Due to central banks | B53: -3054 | C53: -3374 | D53: -3366 | E53: Published component | F53: BNP consolidated cash-flow statement
A54: On-demand deposits with credit institutions | B54: 11927 | C54: 8352 | D54: 9482 | E54: Published component | F54: BNP consolidated cash-flow statement
A55: On-demand loans from credit institutions | B55: -12538 | C55: -10770 | D55: -10608 | E55: Published component | F55: BNP consolidated cash-flow statement
...

Sheet 🧮VARIANCE BRIDGE
A1: BNP PARIBAS — NET INCOME VARIANCE BRIDGE
A2: FY 2022 → FY 2023 → FY 2024 | ECB-style earnings attribution
A3: All values in €M | Drivers linked directly to the consolidated income statement
A4: Net income increased by €1,127M in FY2023 and €713M in FY2024. FY2023 standard Cost of Risk improved by €96M but other net risk losses added a €775M charge; FY2024 standard Cost of Risk increased by €92M while other net risk losses improved by €573M.
A6: FY 2022 → FY 2023 BRIDGE
A7: DRIVER | B7: CHANGE (€M) | C7: RUNNING BALANCE | D7: DIRECTION | E7: SOURCE / STATUS
A8: Opening net income FY2022 (restated) | B8: ='📄 INCOME_STATEMENT'!B44 -> 9848 | C8: =B8 -> 9848 | D8: Restated | E8: Income statement
A9: Net Interest Income | B9: ='📄 INCOME_STATEMENT'!C10-'📄 INCOME_STATEMENT'!B10 -> -1875 | C9: =C8+B9 -> 7973 | D9: =IF(B9>0,"Positive",IF(B9<0,"Negative","Neutral")) -> Negative | E9: NII movement
A10: Fee & Commission Income | B10: ='📄 INCOME_STATEMENT'!C11-'📄 INCOME_STATEMENT'!B11 -> -344 | C10: =C9+B10 -> 7629 | D10: =IF(B10>0,"Positive",IF(B10<0,"Negative","Neutral")) -> Negative | E10: Fees movement
A11: Trading Income | B11: ='📄 INCOME_STATEMENT'!C12-'📄 INCOME_STATEMENT'!B12 -> 994 | C11: =C10+B11 -> 8623 | D11: =IF(B11>0,"Positive",IF(B11<0,"Negative","Neutral")) -> Positive | E11: Trading movement
A12: Other operating activities | B12: ='📄 INCOME_STATEMENT'!C13-'📄 INCOME_STATEMENT'!B13 -> 1253 | C12: =C11+B12 -> 9876 | D12: =IF(B12>0,"Positive",IF(B12<0,"Negative","Neutral")) -> Positive | E12: Other activities movement
A13: Unallocated NBI components | B13: =('📄 INCOME_STATEMENT'!C15-SUM('📄 INCOME_STATEMENT'!C10:C13))-('📄 INCOME_STATEMENT'!B15-SUM('📄 INCOME_STATEMENT'!B10:B13)) -> 416 | C13: =C12+B13 -> 10292 | D13: =IF(B13>0,"Positive",IF(B13<0,"Negative","Neutral")) -> Positive | E13: NBI reconciliation
A14: Operating expenses effect | B14: =-('📄 INCOME_STATEMENT'!C22-'📄 INCOME_STATEMENT'!B22) -> -1092 | C14: =C13+B14 -> 9200 | D14: =IF(B14>0,"Positive",IF(B14<0,"Negative","Neutral")) -> Negative | E14: Lower expenses = positive
A15: Cost of Risk effect | B15: =-('📄 INCOME_STATEMENT'!C27-'📄 INCOME_STATEMENT'!B27) -> 96 | C15: =C14+B15 -> 9296 | D15: =IF(B15>0,"Positive",IF(B15<0,"Negative","Neutral")) -> Positive | E15: Lower Cost of Risk = positive
A16: Other net losses for risk on financial instruments effect | B16: =-('📄 INCOME_STATEMENT'!C28-'📄 INCOME_STATEMENT'!B28) -> -775 | C16: =C15+B16 -> 8521 | D16: =IF(B16>0,"Positive",IF(B16<0,"Negative","Neutral")) -> Negative | E16: Lower other net risk losses = positive
A17: Non-operating items | B17: =('📄 INCOME_STATEMENT'!C33+'📄 INCOME_STATEMENT'!C34+'📄 INCOME_STATEMENT'!C35)-('📄 INCOME_STATEMENT'!B33+'📄 INCOME_STATEMENT'!B34+'📄 INCOME_STATEMENT'!B35) -> -162 | C17: =C16+B17 -> 8359 | D17: =IF(B17>0,"Positive",IF(B17<0,"Negative","Neutral")) -> Negative | E17: Equity earnings / gains / goodwill
A18: Tax effect | B18: =-('📄 INCOME_STATEMENT'!C39-'📄 INCOME_STATEMENT'!B39) -> 387 | C18: =C17+B18 -> 8746 | D18: =IF(B18>0,"Positive",IF(B18<0,"Negative","Neutral")) -> Positive | E18: Lower tax = positive
A19: Discontinued operations & minority interests | B19: =('📄 INCOME_STATEMENT'!C44-'📄 INCOME_STATEMENT'!B44)-SUM(B9:B18) -> 2229 | C19: =C18+B19 -> 10975 | D19: =IF(B19>0,"Positive",IF(B19<0,"Negative","Neutral")) -> Positive | E19: Reconciliation item
A20: Closing net income FY2023 | B20: ='📄 INCOME_STATEMENT'!C44 -> 10975 | C20: =B20 -> 10975 | D20: Reported | E20: Income statement
A21: RECONCILIATION CHECK | B21: =C19-B20 -> 0 | C21: =IF(B21=0,"PASS","CHECK") -> PASS
A23: FY 2023 → FY 2024 BRIDGE
A24: DRIVER | B24: CHANGE (€M) | C24: RUNNING BALANCE | D24: DIRECTION | E24: SOURCE / STATUS
A25: Opening net income FY2023 | B25: ='📄 INCOME_STATEMENT'!C44 -> 10975 | C25: =B25 -> 10975 | D25: Reported | E25: Income statement
A26: Net Interest Income | B26: ='📄 INCOME_STATEMENT'!D10-'📄 INCOME_STATEMENT'!C10 -> 466 | C26: =C25+B26 -> 11441 | D26: =IF(B26>0,"Positive",IF(B26<0,"Negative","Neutral")) -> Positive | E26: NII movement
A27: Fee & Commission Income | B27: ='📄 INCOME_STATEMENT'!D11-'📄 INCOME_STATEMENT'!C11 -> 880 | C27: =C26+B27 -> 12321 | D27: =IF(B27>0,"Positive",IF(B27<0,"Negative","Neutral")) -> Positive | E27: Fees movement
A28: Trading Income | B28: ='📄 INCOME_STATEMENT'!D12-'📄 INCOME_STATEMENT'!C12 -> 1223 | C28: =C27+B28 -> 13544 | D28: =IF(B28>0,"Positive",IF(B28<0,"Negative","Neutral")) -> Positive | E28: Trading movement
A29: Other operating activities | B29: ='📄 INCOME_STATEMENT'!D13-'📄 INCOME_STATEMENT'!C13 -> 142 | C29: =C28+B29 -> 13686 | D29: =IF(B29>0,"Positive",IF(B29<0,"Negative","Neutral")) -> Positive | E29: Other activities movement
A30: Unallocated NBI components | B30: =('📄 INCOME_STATEMENT'!D15-SUM('📄 INCOME_STATEMENT'!D10:D13))-('📄 INCOME_STATEMENT'!C15-SUM('📄 INCOME_STATEMENT'!C10:C13)) -> 246 | C30: =C29+B30 -> 13932 | D30: =IF(B30>0,"Positive",IF(B30<0,"Negative","Neutral")) -> Positive | E30: NBI reconciliation
A31: Operating expenses effect | B31: =-('📄 INCOME_STATEMENT'!D22-'📄 INCOME_STATEMENT'!C22) -> 763 | C31: =C30+B31 -> 14695 | D31: =IF(B31>0,"Positive",IF(B31<0,"Negative","Neutral")) -> Positive | E31: Lower expenses = positive
A32: Cost of Risk effect | B32: =-('📄 INCOME_STATEMENT'!D27-'📄 INCOME_STATEMENT'!C27) -> -92 | C32: =C31+B32 -> 14603 | D32: =IF(B32>0,"Positive",IF(B32<0,"Negative","Neutral")) -> Negative | E32: Lower Cost of Risk = positive
A33: Other net losses for risk on financial instruments effect | B33: =-('📄 INCOME_STATEMENT'!D28-'📄 INCOME_STATEMENT'!C28) -> 573 | C33: =C32+B33 -> 15176 | D33: =IF(B33>0,"Positive",IF(B33<0,"Negative","Neutral")) -> Positive | E33: Lower other net risk losses = positive
A34: Non-operating items | B34: =('📄 INCOME_STATEMENT'!D33+'📄 INCOME_STATEMENT'!D34+'📄 INCOME_STATEMENT'!D35)-('📄 INCOME_STATEMENT'!C33+'📄 INCOME_STATEMENT'!C34+'📄 INCOME_STATEMENT'!C35) -> 262 | C34: =C33+B34 -> 15438 | D34: =IF(B34>0,"Positive",IF(B34<0,"Negative","Neutral")) -> Positive | E34: Equity earnings / gains / goodwill
A35: Tax effect | B35: =-('📄 INCOME_STATEMENT'!D39-'📄 INCOME_STATEMENT'!C39) -> -735 | C35: =C34+B35 -> 14703 | D35: =IF(B35>0,"Positive",IF(B35<0,"Negative","Neutral")) -> Negative | E35: Lower tax = positive
A36: Discontinued operations & minority interests | B36: =('📄 INCOME_STATEMENT'!D44-'📄 INCOME_STATEMENT'!C44)-SUM(B26:B35) -> -3015 | C36: =C35+B36 -> 11688 | D36: =IF(B36>0,"Positive",IF(B36<0,"Negative","Neutral")) -> Negative | E36: Reconciliation item
A37: Closing net income FY2024 | B37: ='📄 INCOME_STATEMENT'!D44 -> 11688 | C37: =B37 -> 11688 | D37: Reported | E37: Income statement
A38: RECONCILIATION CHECK | B38: =C36-B37 -> 0 | C38: =IF(B38=0,"PASS","CHECK") -> PASS
A40: P&L LINE VARIANCE SUMMARY
A41: ITEM | B41: FY 2022 | C41: FY 2023 | D41: Δ€M 22→23 | E41: Δ% 22→23 | F41: FY 2023 | G41: FY 2024 | H41: Δ€M 23→24 | I41: Δ% 23→24
A42: Total NBI | B42: ='📄 INCOME_STATEMENT'!B15 -> 45430 | C42: ='📄 INCOME_STATEMENT'!C15 -> 45874 | D42: =C42-B42 -> 444 | E42: =IFERROR(C42/B42-1,"") -> 0.0097732776 | F42: ='📄 INCOME_STATEMENT'!C15 -> 45874 | G42: ='📄 INCOME_STATEMENT'!D15 -> 48831 | H42: =G42-F42 -> 2957 | I42: =IFERROR(G42/F42-1,"") -> 0.064459171
A43: Net Interest Income | B43: ='📄 INCOME_STATEMENT'!B10 -> 20933 | C43: ='📄 INCOME_STATEMENT'!C10 -> 19058 | D43: =C43-B43 -> -1875 | E43: =IFERROR(C43/B43-1,"") -> -0.08957149 | F43: ='📄 INCOME_STATEMENT'!C10 -> 19058 | G43: ='📄 INCOME_STATEMENT'!D10 -> 19524 | H43: =G43-F43 -> 466 | I43: =IFERROR(G43/F43-1,"") -> 0.024451674
...

Sheet 📈 RATIOS_PROFITABILITY
A1: BNP PARIBAS — PROFITABILITY RATIOS
A2: FY 2022–FY 2024 | ECB/EBA-aligned definitions
A3: Rate metrics in % | EPS in € per share | Values linked to the financial statements where available
A4: Profitability improved across the period: ROE reached 9.28%, ROTE exceeded 10%, and net income margin rose from 21.68% to 23.94%. The key watchpoint is NIM compression from 2.07% to 1.77%, although NII returned to growth in FY2024.
A6: PROFITABILITY SCORECARD
A7: RATIO | B7: FORMULA / DEFINITION | C7: FY 2022 Restated | D7: FY 2023 | E7: FY 2024 | F7: TREND | G7: BENCHMARK / SIGNAL
A8: Return on Equity (ROE) | B8: Net income — group share / average total equity | C8: ='📄 INCOME_STATEMENT'!B44/ANALYTICAL_INPUTS!C7 -> 0.082367652 | D8: ='📄 INCOME_STATEMENT'!C44/ANALYTICAL_INPUTS!C8 -> 0.089599517 | E8: ='📄 INCOME_STATEMENT'!D44/ANALYTICAL_INPUTS!C9 -> 0.092806467 | F8: ↗ | G8: ECB Q2 2024 aggregate: 10.11%
A9: Return on Tangible Equity (ROTE) | B9: Net income — group share / average tangible equity | C9: ='📄 INCOME_STATEMENT'!B44/ANALYTICAL_INPUTS!C10 -> 0.089017848 | D9: ='📄 INCOME_STATEMENT'!C44/ANALYTICAL_INPUTS!C11 -> 0.097036304 | E9: ='📄 INCOME_STATEMENT'!D44/ANALYTICAL_INPUTS!C12 -> 0.10065189 | F9: ↗ | G9: Improving; no external benchmark assessed
A10: Return on Assets (ROA) | B10: Net income — group share / average total assets | C10: ='📄 INCOME_STATEMENT'!B44/ANALYTICAL_INPUTS!C13 -> 0.0037174946 | D10: ='📄 INCOME_STATEMENT'!C44/ANALYTICAL_INPUTS!C14 -> 0.004176778 | E10: ='📄 INCOME_STATEMENT'!D44/ANALYTICAL_INPUTS!C15 -> 0.0044135581 | F10: ↗ | G10: ECB range varies; see BENCHMARKS
A11: Net Interest Margin (NIM) | B11: Net interest income / average earning assets | C11: ='📄 INCOME_STATEMENT'!B10/ANALYTICAL_INPUTS!C16 -> 0.020698128 | D11: ='📄 INCOME_STATEMENT'!C10/ANALYTICAL_INPUTS!C17 -> 0.018198155 | E11: ='📄 INCOME_STATEMENT'!D10/ANALYTICAL_INPUTS!C18 -> 0.01771155 | F11: ↘ | G11: ECB Q2 2024 aggregate: 1.61%
A12: NII Growth | B12: Current-year NII / prior-year NII − 1 | C12: n/a | D12: ='📄 INCOME_STATEMENT'!C10/'📄 INCOME_STATEMENT'!B10-1 -> -0.08957149 | E12: ='📄 INCOME_STATEMENT'!D10/'📄 INCOME_STATEMENT'!C10-1 -> 0.024451674 | F12: ↘↗ | G12: Rate-cycle sensitivity
A13: NBI Growth | B13: Current-year NBI / prior-year NBI − 1 | C13: n/a | D13: ='📄 INCOME_STATEMENT'!C15/'📄 INCOME_STATEMENT'!B15-1 -> 0.0097732776 | E13: ='📄 INCOME_STATEMENT'!D15/'📄 INCOME_STATEMENT'!C15-1 -> 0.064459171 | F13: ↗ | G13: Revenue momentum
A14: Net Income Margin | B14: Net income — group share / total NBI | C14: ='📄 INCOME_STATEMENT'!B44/'📄 INCOME_STATEMENT'!B15 -> 0.21677306 | D14: ='📄 INCOME_STATEMENT'!C44/'📄 INCOME_STATEMENT'!C15 -> 0.23924227 | E14: ='📄 INCOME_STATEMENT'!D44/'📄 INCOME_STATEMENT'!D15 -> 0.23935615 | F14: ↗ | G14: Higher is better
A15: Earnings per Share (€) | B15: Net income — group share / weighted-average shares | C15: ='📄 INCOME_STATEMENT'!B51 -> 7.52 | D15: ='📄 INCOME_STATEMENT'!C51 -> 8.58 | E15: ='📄 INCOME_STATEMENT'!D51 -> 9.57 | F15: ↗ | G15: Strong EPS growth
A16: Net Income 2-Year CAGR (FY22–FY24) | B16: (Net income FY2024 / FY2022)^(1/2) − 1 | C16: n/a | D16: n/a | E16: =('📄 INCOME_STATEMENT'!D44/'📄 INCOME_STATEMENT'!B44)^(1/2)-1 -> 0.08942185 | F16: ↗ | G16: Strong delivery
A19: METHODOLOGY NOTES
A20: Tangible equity equals shareholders’ equity less goodwill and intangible assets. Earning assets comprise customer and bank loans plus debt securities at amortised cost and FVOCI. Average-balance denominators and their annual-report source sections are documented in ANALYTICAL_INPUTS.
A22: MANAGEMENT TAKEAWAY
A23: The earnings profile strengthened through FY2024, with rising returns, margins, and EPS. On the consistent restated basis, net income grew at an 8.94% two-year CAGR. Continued NIM compression means future growth must increasingly rely on fees, trading, cost discipline, and balance-sheet efficiency.

Sheet 📈 RATIOS_LIQUIDITY
A1: BNP PARIBAS — LIQUIDITY RATIOS
A2: FY 2022–FY 2024 | CRR Article 412 | LCR Delegated Act | NSFR CRR2
A3: Source: BNP Paribas Pillar 3 annual disclosures | HQLA values in €M
A4: Liquidity ratios remained above the 100% regulatory minimum throughout the period. FY2024 LCR closed at 137% and NSFR at 111.75%, while customer deposits exceeded customer loans; HQLA declined to €380,615M.
A6: LIQUIDITY SCORECARD
A7: RATIO | B7: REGULATORY DEFINITION | C7: FY 2022 | D7: FY 2023 | E7: FY 2024 | F7: TREND | G7: MINIMUM / TARGET | H7: SIGNAL
A8: Liquidity Coverage Ratio (LCR) | B8: HQLA / 30-day stressed net cash outflows | C8: 1.29 | D8: 1.48 | E8: 1.37 | F8: ↗↘ | G8: ≥100% | H8: Compliant
A9: Net Stable Funding Ratio (NSFR) | B9: Available stable funding / required stable funding | C9: 1.1505 | D9: 1.1592 | E9: 1.1175 | F9: → | G9: ≥100% | H9: Compliant
A10: High Quality Liquid Assets (€M) | B10: Reported HQLA stock, predominantly Level 1 assets | C10: 454812 | D10: 408476 | E10: 380615 | F10: ↘ | G10: Liquidity buffer | H10: Strong stock; declining
A11: Loan-to-Deposit Ratio | B11: Gross customer loans / customer deposits | C11: ='🏦 BALANCE_SHEET'!B20/'🏦 BALANCE_SHEET'!B45 -> 0.85017102 | D11: ='🏦 BALANCE_SHEET'!C20/'🏦 BALANCE_SHEET'!C45 -> 0.86915267 | E11: ='🏦 BALANCE_SHEET'!D20/'🏦 BALANCE_SHEET'!D45 -> 0.86982163 | F11: → | G11: <100% ideal | H11: Deposits exceed customer loans
A12: Deposit Growth | B12: Annual change in customer deposits | C12: n/a | D12: ='🏦 BALANCE_SHEET'!C45/'🏦 BALANCE_SHEET'!B45-1 -> -0.019351107 | E12: ='🏦 BALANCE_SHEET'!D45/'🏦 BALANCE_SHEET'!C45-1 -> 0.046844415 | F12: ↘↗ | G12: n/a | H12: Recovered in FY2024
A15: REGULATORY NOTES
A16: LCR and NSFR are assessed against the 100% minimum. A loan-to-deposit ratio below 100% supports a deposit-funded customer lending profile, although it does not capture the full funding structure of the Group.
A20: MANAGEMENT TAKEAWAY
A21: BNP Paribas maintains liquidity ratios above the stated minimum and customer deposits above customer loans. The principal watchpoint is the decline in HQLA from €454,812M to €380,615M and the moderation of NSFR.

Sheet 📈 RATIOS_CAPITAL
A1: BNP PARIBAS — CAPITAL ADEQUACY RATIOS
A2: FY 2022–FY 2024 | CRD VI / CRR3 | ECB SSM framework
A3: Source: BNP Paribas annual results and Pillar 3 disclosures | Capital values in €M
A4: BNP Paribas reported capital ratios above the stated comparison levels across the period. FY2024 CET1 was 12.87% and leverage 4.62%. These are analytical regulatory references only; no BNP-specific SREP threshold or complete applicable requirement is asserted.
A6: REGULATORY CAPITAL SCORECARD
A7: RATIO | B7: CRR3 / ECB DEFINITION | C7: FY 2022 | D7: FY 2023 | E7: FY 2024 | F7: TREND | G7: REGULATORY REFERENCE USED | H7: SIGNAL
A8: Common Equity Tier 1 (CET1) | B8: CET1 capital / total RWA | C8: 0.1233 | D8: 0.132 | E8: 0.1287 | F8: ↗↘ | G8: Analytical comparison only | H8: No SREP threshold asserted
A9: Tier 1 Ratio | B9: Tier 1 capital / total RWA | C9: 0.1389 | D9: 0.1528 | E9: 0.1493 | F9: ↗↘ | G9: 10.5% base reference | H9: Above stated base reference
A10: Total Capital Ratio | B10: Total capital / total RWA | C10: 0.1619 | D10: 0.173 | E10: 0.1713 | F10: ↗↘ | G10: 12.5% base reference | H10: Above stated base reference
A11: Leverage Ratio | B11: Tier 1 capital / total exposure measure | C11: 0.0436 | D11: 0.0458 | E11: 0.0462 | F11: ↗ | G11: 3.0% leverage reference | H11: Above stated base reference
A14: CAPITAL STRUCTURE & RWA
A15: COMPONENT (€M) | B15: FY 2022 | C15: FY 2023 | D15: FY 2024 | E15: Δ€M 22→23 | F15: Δ€M 23→24 | G15: FY2024 SIGNAL
A16: CET1 Capital | B16: 91828 | C16: 92857 | D16: 98128 | E16: =C16-B16 -> 1029 | F16: =D16-C16 -> 5271 | G16: Growing
A17: Additional Tier 1 (AT1 / CoCo) | B17: 11616 | C17: 14644 | D17: 15640 | E17: =C17-B17 -> 3028 | F17: =D17-C17 -> 996 | G17: Growing
A18: Tier 1 Capital | B18: 103445 | C18: 107501 | D18: 113768 | E18: =C18-B18 -> 4056 | F18: =D18-C18 -> 6267 | G18: Growing
A19: Tier 2 Capital | B19: 17117 | C19: 14243 | D19: 16813 | E19: =C19-B19 -> -2874 | F19: =D19-C19 -> 2570 | G19: Recovered
A20: Total Capital | B20: =B18+B19 -> 120562 | C20: =C18+C19 -> 121744 | D20: =D18+D19 -> 130581 | E20: =C20-B20 -> 1182 | F20: =D20-C20 -> 8837 | G20: Record level
A21: Risk-Weighted Assets | B21: 744851 | C21: 703694 | D21: 762247 | E21: =C21-B21 -> -41157 | F21: =D21-C21 -> 58553 | G21: Higher intensity
A22: Credit RWA | B22: 579635 | C22: 535141 | D22: 579602 | E22: =C22-B22 -> -44494 | F22: =D22-C22 -> 44461 | G22: Recovered
A23: Market RWA | B23: 25543 | C23: 28783 | D23: 28123 | E23: =C23-B23 -> 3240 | F23: =D23-C23 -> -660 | G23: Stable
A24: Operational RWA | B24: 61656 | C24: 58897 | D24: 64964 | E24: =C24-B24 -> -2759 | F24: =D24-C24 -> 6067 | G24: Increased
A27: FY2024 CAPITAL COMPARISON
A28: METRIC | B28: FY2024 RATIO | C28: REFERENCE | D28: HEADROOM (pp) | E28: STATUS
A29: CET1 | B29: 0.1287 | C29: No SREP threshold asserted | D29: n/a | E29: REFERENCE ONLY
A30: Tier 1 | B30: =E9 -> 0.1493 | C30: 0.105 | D30: =B30-C30 -> 0.0443 | E30: =IF(D30>0,"PASS","CHECK") -> PASS
A31: Total Capital | B31: =E10 -> 0.1713 | C31: 0.125 | D31: =B31-C31 -> 0.0463 | E31: =IF(D31>0,"PASS","CHECK") -> PASS
A32: Leverage | B32: =E11 -> 0.0462 | C32: 0.03 | D32: =B32-C32 -> 0.0162 | E32: =IF(D32>0,"PASS","CHECK") -> PASS
A34: MANAGEMENT TAKEAWAY
A35: Capital generation remained strong, with CET1 capital reaching €98,128M and total capital €130,581M in FY2024. RWA increased to €762,247M, moderating ratios from FY2023 peaks; reported ratios remained above the stated base references used in this workbook, and leverage continued to improve.

Sheet 📈 RATIOS_ASSET_QUALITY
A1: BNP PARIBAS — ASSET QUALITY RATIOS
A2: FY 2022–FY 2024 | IFRS 9 ECL | EBA NPL definition
A3: Source: BNP Paribas Pillar 3 and annual-results credit-risk disclosures | Monetary values in €M
A4: Credit quality improved over the period: the NPL ratio declined to 1.6%, Stage 1 and Stage 2 ECL balances fell, and total impairment reduced to €17,181M. Coverage remained adequate at 69.7%, although its gradual decline is a watchpoint.
A6: ASSET QUALITY SCORECARD
A7: METRIC | B7: EBA / IFRS 9 DEFINITION | C7: FY 2022 Restated | D7: FY 2023 | E7: FY 2024 | F7: TREND | G7: TARGET / BENCHMARK | H7: SIGNAL
A8: Non-Performing Loan Ratio | B8: 90+ days past due or unlikely to pay without collateral | C8: 0.017 | D8: 0.017 | E8: 0.016 | F8: ↘ | G8: ECB Q2 2024 aggregate: 2.30% | H8: Better than EU average
A9: Coverage Ratio | B9: Loan-loss allowances / gross Stage 3 exposure | C9: 0.725 | D9: 0.717 | E9: 0.697 | F9: ↘ | G9: >50%; higher is stronger | H9: Adequate; declining
A10: Cost of Risk (€M) | B10: BNP-reported Cost of Risk for the period | C10: ='📄 INCOME_STATEMENT'!B27 -> 3003 | D10: ='📄 INCOME_STATEMENT'!C27 -> 2907 | E10: ='📄 INCOME_STATEMENT'!D27 -> 2999 | F10: ↗↘ | G10: Reported Cost of Risk | H10: Standard definition; +3.2% in FY2024
A11: Cost of Risk (bps) | B11: BNP-reported Cost of Risk in basis points | C11: ='📄 INCOME_STATEMENT'!B49 -> 31 | D11: ='📄 INCOME_STATEMENT'!C49 -> 32 | E11: ='📄 INCOME_STATEMENT'!D49 -> 33 | F11: ↗ | G11: ECB Q2 2024 aggregate: 47 bps | H11: Below ECB Q2 2024 sector reference
A12: Stage 1 ECL (€M) | B12: 12-month expected credit losses | C12: 2035 | D12: 1938 | E12: 1785 | F12: ↘ | G12: Lower performing ECL | H12: Improving
A13: Stage 2 ECL (€M) | B13: Lifetime ECL for increased credit risk | C13: 2860 | D13: 2416 | E13: 1939 | F13: ↘ | G13: Rising balance is warning | H13: Improving
A14: Stage 3 Allowance (€M) | B14: Allowance on doubtful / non-performing assets | C14: 13616 | D14: 13361 | E14: 13457 | F14: → | G14: Stable coverage support | H14: Stable
A15: Total Financial-Asset Impairment (€M) | B15: Stage 1 + Stage 2 + Stage 3 allowances | C15: 18511 | D15: 17715 | E15: 17181 | F15: ↘ | G15: Lower is favourable if quality holds | H15: Improving
A18: IMPAIRMENT MOVEMENT ANALYSIS
A19: COMPONENT (€M) | B19: FY 2022 | C19: FY 2023 | D19: FY 2024 | E19: Δ€M 22→23 | F19: Δ€M 23→24 | G19: FY2024 SIGNAL
A20: Stage 1 ECL | B20: =C12 -> 2035 | C20: =D12 -> 1938 | D20: =E12 -> 1785 | E20: =C20-B20 -> -97 | F20: =D20-C20 -> -153 | G20: Declining
A21: Stage 2 ECL | B21: =C13 -> 2860 | C21: =D13 -> 2416 | D21: =E13 -> 1939 | E21: =C21-B21 -> -444 | F21: =D21-C21 -> -477 | G21: Declining
A22: Stage 3 Allowance | B22: =C14 -> 13616 | C22: =D14 -> 13361 | D22: =E14 -> 13457 | E22: =C22-B22 -> -255 | F22: =D22-C22 -> 96 | G22: Stable
A23: Total Impairment | B23: =C15 -> 18511 | C23: =D15 -> 17715 | D23: =E15 -> 17181 | E23: =C23-B23 -> -796 | F23: =D23-C23 -> -534 | G23: Declining
A26: IFRS 9 STAGING NOTE
A27: Stage 1 represents performing assets subject to 12-month ECL; Stage 2 represents exposures with significantly increased credit risk and lifetime ECL; Stage 3 represents credit-impaired or non-performing exposures.
A30: MANAGEMENT TAKEAWAY
A31: BNP Paribas’ credit-risk profile improved through FY2024, with lower NPLs and falling early-stage ECL balances. Cost of Risk was 33 bps versus the ECB Q2 2024 sector reference of 47 bps; declining coverage warrants continued monitoring.

Sheet 📈 RATIOS_EFFICIENCY
A1: BNP PARIBAS — EFFICIENCY RATIOS
A2: FY 2022–FY 2024 | Operating leverage and cost-efficiency analysis
A3: Analytical comparison: cost-to-income ratio below 66% | Positive operating leverage above 0 pp
A4: Efficiency improved materially in FY2024: NBI grew 6.45%, operating expenses declined 2.46%, and CIR fell to 61.83%. This generated positive operating leverage of 8.91 pp after the FY2023 deterioration.
A6: EFFICIENCY SCORECARD
A7: METRIC | B7: FORMULA / DEFINITION | C7: FY 2022 Restated | D7: FY 2023 | E7: FY 2024 | F7: TREND | G7: COMPARISON | H7: SIGNAL
A8: Cost-to-Income Ratio (CIR) | B8: Total operating expenses / total NBI | C8: ='📄 INCOME_STATEMENT'!B22/'📄 INCOME_STATEMENT'!B15 -> 0.65736298 | D8: ='📄 INCOME_STATEMENT'!C22/'📄 INCOME_STATEMENT'!C15 -> 0.6748049 | E8: ='📄 INCOME_STATEMENT'!D22/'📄 INCOME_STATEMENT'!D15 -> 0.61831623 | F8: ↗↘ | G8: <66.0% | H8: Below comparison in FY2024
A9: CIR vs 66% Comparison (pp) | B9: CIR less 66.0% analytical comparison | C9: =C8-66% -> -0.002637024 | D9: =D8-66% -> 0.0148049 | E9: =E8-66% -> -0.041683766 | F9: ↗↘ | G9: Negative = pass | H9: Below comparison in FY2024
A10: NBI Growth | B10: Current-year NBI / prior-year NBI − 1 | C10: n/a | D10: ='📄 INCOME_STATEMENT'!C15/'📄 INCOME_STATEMENT'!B15-1 -> 0.0097732776 | E10: ='📄 INCOME_STATEMENT'!D15/'📄 INCOME_STATEMENT'!C15-1 -> 0.064459171 | F10: ↗ | G10: Positive growth | H10: Strong FY2024 growth
A11: Operating Expense Growth | B11: Current-year OpEx / prior-year OpEx − 1 | C11: n/a | D11: ='📄 INCOME_STATEMENT'!C22/'📄 INCOME_STATEMENT'!B22-1 -> 0.036565765 | E11: ='📄 INCOME_STATEMENT'!D22/'📄 INCOME_STATEMENT'!C22-1 -> -0.024647887 | F11: ↗↘ | G11: Below NBI growth | H11: Costs declined in FY2024
A12: Operating Leverage (pp) | B12: NBI growth less OpEx growth | C12: n/a | D12: =(D10-D11)*100 -> -2.6792487 | E12: =(E10-E11)*100 -> 8.9107058 | F12: ↗ | G12: >0 pp | H12: Positive in FY2024
A13: Capex / NBI | B13: Capital expenditure / total NBI | C13: 0.0557 | D13: 0.0483 | E13: 0.0437 | F13: ↘ | G13: Efficient reinvestment | H13: Declining intensity
A16: COMPARISON ASSESSMENT
A17: TEST | B17: FY 2022 | C17: FY 2023 | D17: FY 2024 | E17: FY2024 STATUS | F17: COMMENT
A18: CIR below 66% analytical comparison | B18: =C8<66% -> TRUE | C18: =D8<66% -> FALSE | D18: =E8<66% -> TRUE | E18: =IF(D18,"PASS","CHECK") -> PASS | F18: CIR moved below comparison
A19: Operating leverage above 0 pp | B19: ="n/a" -> n/a | C19: =D12>0 -> FALSE | D19: =E12>0 -> TRUE | E19: =IF(D19,"PASS","CHECK") -> PASS | F19: Strong positive leverage
A20: NBI growth exceeds OpEx growth | B20: ="n/a" -> n/a | C20: =D10>D11 -> FALSE | D20: =E10>E11 -> TRUE | E20: =IF(D20,"PASS","CHECK") -> PASS | F20: Revenue outpaced costs
A23: MANAGEMENT TAKEAWAY
A24: FY2024 delivered stronger revenue, lower expenses, positive operating leverage, and a CIR below the workbook’s 66% analytical comparison. The key forward-looking sensitivity is continued NIM pressure and the ability to maintain positive operating leverage.

Sheet 📉 TRENDS_CHARTS
A1: BNP PARIBAS — FINANCIAL TRENDS DASHBOARD
A2: FY 2022 Restated–FY 2024 | Earnings, returns, capital, credit quality, and efficiency
A3: Six verified native Excel charts | Values live-linked to the workbook’s financial statements and ratio schedules
A5: STORY IN BRIEF
A6: FY2024 delivered stronger earnings and efficiency: NBI reached €48,831M, net income rose to €11,688M, and CIR improved to 61.83%. ROE and ROTE continued to rise, CET1 remained strong on an analytical-comparison basis, and the NPL ratio improved to 1.6%. The principal watchpoints are lower NIM, declining NPL coverage, and capital ratios moderating from FY2023 peaks. No BNP-specific SREP threshold is asserted.
A10: TREND CHARTS
A68: KEY FINDINGS
A70: 1. Earnings — FY2024 NBI rose 6.4% and net income attributable to equity holders increased 6.5%.
A71: 2. Returns — ROE and ROTE improved each year, reaching 9.28% and 10.07% in FY2024.
A72: 3. Capital — CET1 closed FY2024 at 12.87%; regulatory references are analytical comparisons only and no BNP-specific SREP threshold is asserted.
A73: 4. Credit — NPL improved to 1.6% versus the 2.3% ECB reference; Cost of Risk increased to 33 bps but remained below the 47 bps sector reference.
A74: 5. Efficiency — CIR improved to 61.83%, below the workbook’s 66% analytical comparison.

Sheet 💧 WATERFALL_NET_INCOME
A1: BNP PARIBAS — NET INCOME WATERFALL
A2: FY 2022 → FY 2023 → FY 2024 | Income-statement driver attribution
A3: All values in €M | Green = positive contribution | Red = negative contribution | Grey = reported net income
A4: Net income increased from €9,848M in restated FY2022 to €11,688M in FY2024, an 8.9% two-year CAGR. Standard Cost of Risk improved in FY2023 and increased slightly in FY2024, while other net risk losses declined from €775M to €202M.
A6: NET INCOME BRIDGE CHART
A29: FY 2022 → FY 2023 DRIVER TABLE
A30: DRIVER | B30: CHANGE (€M) | C30: RUNNING BALANCE | D30: DIRECTION | E30: SOURCE / INTERPRETATION | F30: DISPLAY LABEL
A31: Opening net income FY2022 (restated) | B31: ='📄 INCOME_STATEMENT'!B44 -> 9848 | C31: =B31 -> 9848 | D31: Restated | E31: Income statement | F31: =IF(OR(D31="Reported",D31="Restated"),"€"&TEXT(B31,"#,##0")&"M",IF(B31>=0,"+€","−€")&TEXT(ABS(B31),"#,##0")&"M") -> €9,848M
A32: Net Interest Income | B32: ='📄 INCOME_STATEMENT'!C10-'📄 INCOME_STATEMENT'!B10 -> -1875 | C32: =C31+B32 -> 7973 | D32: =IF(B32>0,"Positive",IF(B32<0,"Negative","Neutral")) -> Negative | E32: NII movement | F32: =IF(OR(D32="Reported",D32="Restated"),"€"&TEXT(B32,"#,##0")&"M",IF(B32>=0,"+€","−€")&TEXT(ABS(B32),"#,##0")&"M") -> −€1,875M
A33: Fee & Commission Income | B33: ='📄 INCOME_STATEMENT'!C11-'📄 INCOME_STATEMENT'!B11 -> -344 | C33: =C32+B33 -> 7629 | D33: =IF(B33>0,"Positive",IF(B33<0,"Negative","Neutral")) -> Negative | E33: Fees movement | F33: =IF(OR(D33="Reported",D33="Restated"),"€"&TEXT(B33,"#,##0")&"M",IF(B33>=0,"+€","−€")&TEXT(ABS(B33),"#,##0")&"M") -> −€344M
